<!DOCTYPE html>
<html>
    <head>
        <title>Technical Documentation - JavaScript: Using Promises</title>
        <link href="https://fonts.googleapis.com/css?family=PT+Sans:400,700|Nanum+Gothic+Coding:400,700" rel="stylesheet">
        <link href="asset/prism.css" rel="stylesheet">
        <link href="main.css" rel="stylesheet">
        <script src="script.js" defer></script>
        <meta name="viewport" content="width=device-width, initial-scale=1">
        <link rel="stylesheet" href="https://use.fontawesome.com/releases/v5.8.1/css/all.css" integrity="sha384-50oBUHEmvpQ+1lW4y57PTFmhCaXp0ML5d60M1M7uH2+nqUivzIebhndOJK28anvf" crossorigin="anonymous">
    </head>
    <body>
        <nav id="navbar">
            <header>
                JavaScript: Using Promises
            </header>
            <button class="nav-button"><i class="fas fa-angle-double-down"></i></button>
            <div class="nav-links">
                <ul>
                    <li><a href="#Introduction" class="nav-link">Introduction</a></li>
                    <li><a href="#Guarantees" class="nav-link">Guarantees</a></li>
                    <li><a href="#Chaining" class="nav-link">Chaining</a></li>
                    <li><a href="#Error_propagation" class="nav-link">Error propagation</a></li>
                    <li><a href="#Promise_rejection_events" class="nav-link">Promise rejection events</a></li>
                    <li><a href="#Creating_a_Promise_around_an_old_callback_API" class="nav-link">Creating a Promise around an old callback API</a></li>
                    <li><a href="#Composition" class="nav-link">Composition</a></li>
                    <li><a href="#Timing" class="nav-link">Timing</a></li>
                    <li><a href="#Nesting" class="nav-link">Nesting</a></li>
                    <li><a href="#Common_mistakes" class="nav-link">Common mistakes</a></li>
                    <li><a href="#When_promises_and_tasks_collide" class="nav-link">When promises and tasks collide</a></li>
                </ul>
            </div>
        </nav>
        <main id="main-doc">
            <section class="main-section" id="Introduction">
                <header>INTRODUCTION</header>
                <p>A <code class="language-none">Promise</code> is an object representing the eventual completion or failure of an asynchronous operation. Since most people are consumers of already-created promises, this guide will explain consumption of returned promises before explaining how to create them.</p>
                <p>Essentially, a promise is a returned object to which you attach callbacks, instead of passing callbacks into a function.</p>
                <p>Imagine a function, <code class="language-javascript">createAudioFileAsync()</code>, which asynchronously generates a sound file given a configuration record and two callback functions, one called if the audio file is successfully created, and the other called if an error occurs.</p>
                <p>Here's some code that uses <code class="language-javascript">createAudioFileAsync()</code>:</p>
                <pre class="line-numbers language-javascript"><code class="language-javascript">
function successCallback(result) {
    console.log("Audio file ready at URL: " + result);
}

function failureCallback(error) {
    console.error("Error generating audio file: " + error);
}

createAudioFileAsync(audioSettings, successCallback, failureCallback);
                </code></pre>
                <p>Modern functions return a promise that you can attach your callbacks to instead:</p>
                <p>If <code class="language-javascript">createAudioFileAsync()</code> were rewritten to return a promise, using it could be as simple as this:</p>
                <pre class="language-javascript line-numbers"><code>
createAudioFileAsync(audioSettings).then(successCallback, failureCallback);
                </code></pre>
                <p>That's shorthand for:</p>
                <pre class="language-javascript line-numbers"><code>
const promise = createAudioFileAsync(audioSettings); 
promise.then(successCallback, failureCallback);
                </code></pre>
                <p>We call this an <em>asynchronous function call</em>. This convention has several advantages. We will explore each one.</p>
            </section>
            <section class="main-section" id="Guarantees">
                <header>GUARANTEES</header>
                <p>Unlike old-fashioned passed-in callbacks, a promise comes with some guarantees:</p>
                <ul>
                    <li>Callbacks will never be called before the completion of the current run of the JavaScript event loop.</li>
                    <li>Callbacks added with <code class="language-javascript">then()</code>, as above, will be called even after the success or failure of the asynchronous operation.</li>
                    <li>Multiple callbacks may be added by calling <code class="language-javascript">then()</code> several times. Each callback is executed one after another, in the order in which they were inserted.</li>
                </ul>
                <p>One of the great things about using promises is <b>chaining</b>.</p>
            </section>
            <section class="main-section" id="Chaining">
                <header>CHAINING</header>
                <p>A common need is to execute two or more asynchronous operations back to back, where each subsequent operation starts when the previous operation succeeds, with the result from the previous step. We accomplish this by creating a <b>promise chain</b>.</p>
                <p>Here's the magic: the then() function returns a new promise, different from the original:</p>
                <pre class="language-javascript line-numbers"><code>
const promise = doSomething();
const promise2 = promise.then(successCallback, failureCallback);
or
const promise2 = doSomething().then(successCallback, failureCallback);
                </code></pre>
                <p>This second promise (promise2) represents the completion not just of doSomething(), but also of the successCallback or failureCallback you passed in, which can be other asynchronous functions returning a promise. When that's the case, any callbacks added to promise2 get queued behind the promise returned by either successCallback or failureCallback.</p>
                <p>Basically, each promise represents the completion of another asynchronous step in the chain.</p>
                <p>In the old days, doing several asynchronous operations in a row would lead to the classic callback pyramid of doom:</p>
                <pre class="language-javascript line-numbers"><code> 
doSomething(function(result) {
    doSomethingElse(result, function(newResult) {
        doThirdThing(newResult, function(finalResult) {
        console.log('Got the final result: ' + finalResult);
        }, failureCallback);
    }, failureCallback);
    }, failureCallback);
                </code></pre>
                <p>With modern functions, we attach our callbacks to the returned promises instead, forming a promise chain:</p>
                <pre class="language-javascript line-numbers"><code>
doSomething()
    .then(function(result) {
    return doSomethingElse(result);
    })
    .then(function(newResult) {
    return doThirdThing(newResult);
    })
    .then(function(finalResult) {
    console.log('Got the final result: ' + finalResult);
    })
    .catch(failureCallback);

                </code></pre>
                <p>The arguments to then are optional, and catch(failureCallback) is short for then(null, failureCallback). You might see this expressed with arrow functions instead:</p>
                <pre class="language-javascript line-numbers"><code>
doSomething()
    .then(result => doSomethingElse(result))
    .then(newResult => doThirdThing(newResult))
    .then(finalResult => {
    console.log(`Got the final result: ${finalResult}`);
    })
    .catch(failureCallback);
                </code></pre>
                <p><b>Important:</b> Always return results, otherwise callbacks won't catch the result of a previous promise (with arrow functions <code class="language-javascript">() => x</code> is short for <code class="language-javascript">() => { return x; })</code>.</p>
                <h3><span>Chaining after a catch</span></h3>

                <p>It's possible to chain after a failure, i.e. a catch, which is useful to accomplish new actions even after an action failed in the chain. Read the following example:</p>
                <pre class="language-javascript line-numbers"><code>
new Promise((resolve, reject) => {
    console.log('Initial');

    resolve();
})
.then(() => {
    throw new Error('Something failed');
        
    console.log('Do this');
})
.catch(() => {
    console.error('Do that');
})
.then(() => {
    console.log('Do this, no matter what happened before');
});
                </code></pre>

                <p>This will output the following text:</p>
                <pre class="language-javascript line-numbers"><code>
Initial
Do that
Do this, no matter what happened before
                </code></pre>
                <p><b>Note:</b> The text "Do this" is not displayed because the "Something failed" error caused a rejection.</p>
            </section>

            <section class="main-section" id="Error_propagation">
                <header>ERROR PROPAGATION</header>
                <p>You might recall seeing <code class="language-javascript">failureCallback</code> three times in the pyramid of doom earlier, compared to only once at the end of the promise chain:</p>
                <pre class="language-javascript line-numbers"><code>
doSomething()
    .then(result => doSomethingElse(result))
    .then(newResult => doThirdThing(newResult))
    .then(finalResult => console.log(`Got the final result: ${finalResult}`))
    .catch(failureCallback);
                </code></pre>
                <p>If there's an exception, the browser will look down the chain for <code class="language-javascript">.catch()</code> handlers or onRejected. This is very much modeled after how synchronous code works:</p>
                <pre class="language-javascript line-numbers"><code>
try {
    const result = syncDoSomething();
    const newResult = syncDoSomethingElse(result);
    const finalResult = syncDoThirdThing(newResult);
    console.log(`Got the final result: ${finalResult}`);
    } catch(error) {
    failureCallback(error);
    }
                </code></pre>
                <p>This symmetry with asynchronous code culminates in the <code class="language-javascript">async/await</code> syntactic sugar in ECMAScript 2017:</p>
                <pre class="language-javascript line-numbers"><code>
async function foo() {
    try {
        const result = await doSomething();
        const newResult = await doSomethingElse(result);
        const finalResult = await doThirdThing(newResult);
        console.log(`Got the final result: ${finalResult}`);
    } catch(error) {
        failureCallback(error);
    }
}
                </code></pre>
                <p>It builds on promises, e.g. <code class="language-javascript">doSomething()</code> is the same function as before. You can read more about the syntax <a href="https://developers.google.com/web/fundamentals/primers/async-functions">here</a>.</p>
                <p>Promises solve a fundamental flaw with the callback pyramid of doom, by catching all errors, even thrown exceptions and programming errors. This is essential for functional composition of asynchronous operations.</p>
            </section>
            <section class="main-section" id="Promise_rejection_events">
                <header>PROMISE REJECTION EVENTS</header>
                <p>Whenever a promise is rejected, one of two events is sent to the global scope (generally, this is either the window or, if being used in a web worker, it's the Worker or other worker-based interface). The two events are:</p>
                <dl>
                    <dt>rejectionhandled</dt>
                        <dd>Sent when a promise is rejected, after that rejection has been handled by the executor's reject function.</dd>
                    <dt>unhandledrejection</dt>
                        <dd>Sent when a promise is rejected but there is no rejection handler available.</dd>
                </dl>
                <p>In both cases, the event (of type <code class="language-javascript">PromiseRejectionEvent</code>) has as members a <code class="language-javascript">promise</code> property indicating the promise that was rejected, and a <code class="language-javascript">reason</code> property that provides the reason given for the promise to be rejected.</p>
                <p>These make it possible to offer fallback error handling for promises, as well as to help debug issues with your promise management. These handlers are global per context, so all errors will go to the same event handlers, regardless of source.</p>
                <p>One case of special usefulness: when writing code for Node.js, it's common that modules you include in your project may have unhandled rejected promises. These get logged to the console by the Node runtime. You can capture these for analysis and handling by your code—or just to avoid having them cluttering up your output—by adding a handler for the unhandledrejection event, like this:</p>
                <pre class="language-javascript line-numbers"><code>
window.addEventListener("unhandledrejection", event => {
    /* You might start here by adding code to examine the
        promise specified by event.promise and the reason in
        event.reason */
    
    event.preventDefault();
    }, false);
                </code></pre>
                <p>By calling the event's <code class="language-javascript">preventDefault()</code> method, you tell the JavaScript runtime not to do its default action when rejected promises go unhandled. That default action usually involves logging the error to console, and this is indeed the case for Node.</p>
                <p>Ideally, of course, you should examine the rejected promises to make sure none of them are actual code bugs before just discarding these events.</p>
            </section>
            <section class="main-section" id="Creating_a_Promise_around_an_old_callback_API">
                <header>CREATING A PROMISE AROUND AN OLD CALLBACK API</header>
                <p>A Promise can be created from scratch using its constructor. This should be needed only to wrap old APIs.</p>
                <p>In an ideal world, all asynchronous functions would already return promises. Unfortunately, some APIs still expect success and/or failure callbacks to be passed in the old way. The most obvious example is the <code class="language-javascript line-numbers">setTimeout()</code> function:</p>
                <pre><code class="language-javascript line-numbers">
setTimeout(() => saySomething("10 seconds passed"), 10*1000);
                </code></pre>
                <p>Mixing old-style callbacks and promises is problematic. If saySomething() fails or contains a programming error, nothing catches it. <code class="language-javascript">setTimeout</code> is to blame for this.</p>
                <p>Luckily we can wrap <code class="language-javascript">setTimeout</code> in a promise. Best practice is to wrap problematic functions at the lowest possible level, and then never call them directly again:</p>
                <pre class="language-javascript line-numbers"><code>
const wait = ms => new Promise(resolve => setTimeout(resolve, ms));

wait(10*1000).then(() => saySomething("10 seconds")).catch(failureCallback);
                </code></pre>
                <p>Basically, the promise constructor takes an executor function that lets us resolve or reject a promise manually. Since <code class="language-javascript">setTimeout()</code> doesn't really fail, we left out reject in this case.</p>
            </section>
            <section class="main-section" id="Composition">
                <header>COMPOSITION</header>
                <p><code class="language-javascript">Promise.resolve()</code> and <code class="language-javascript">Promise.reject()</code> are shortcuts to manually create an already resolved or rejected promise respectively. This can be useful at times.</p>
                <p><code class="language-javascript">Promise.all()</code> and <code class="language-javascript">Promise.race()</code> are two composition tools for running asynchronous operations in parallel.</p>
                <p>We can start operations in parallel and wait for them all to finish like this:</p>
                <pre class="language-javascript line-numbers"><code>
Promise.all([func1(), func2(), func3()])
.then(([result1, result2, result3]) => { /* use result1, result2 and result3 */ });
                </code></pre>
                <p>Sequential composition is possible using some clever JavaScript:</p>
                <pre class="language-javascript line-numbers"><code>
[func1, func2, func3].reduce((p, f) => p.then(f), Promise.resolve())
.then(result3 => { /* use result3 */ });
                </code></pre>
                <p>Basically, we reduce an array of asynchronous functions down to a promise chain equivalent to: <code class="language-javascript">Promise.resolve().then(func1).then(func2).then(func3);</code></p>
                <p>This can be made into a reusable compose function, which is common in functional programming:</p>
                <pre class="language-javascript line-numbers"><code>
const applyAsync = (acc,val) => acc.then(val);
const composeAsync = (...funcs) => x => funcs.reduce(applyAsync, Promise.resolve(x));
                </code></pre>
                <p>The <code class="language-javascript">composeAsync()</code> function will accept any number of functions as arguments, and will return a new function that accepts an initial value to be passed through the composition pipeline:</p>
                <pre class="language-javascript line-numbers"><code>
const transformData = composeAsync(func1, func2, func3);
const result3 = transformData(data);
                </code></pre>
                <p>In ECMAScript 2017, sequential composition can be done more simply with async/await:</p>
                <pre class="language-javascript line-numbers"><code>
let result;
for (const f of [func1, func2, func3]) {
result = await f(result);
}
/* use last result (i.e. result3) */
                </code></pre>
            </section>
            <section class="main-section" id="Timing">
                <header>TIMING</header>
                <p></p>To avoid surprises, functions passed to <code class="language-javascript">then()</code> will never be called synchronously, even with an already-resolved promise:</p>
                <pre class="language-javascript line-numbers"><code>
Promise.resolve().then(() => console.log(2));
console.log(1); // 1, 2
                </code></pre>

                <p>Instead of running immediately, the passed-in function is put on a microtask queue, which means it runs later when the queue is emptied at the end of the current run of the JavaScript event loop, i.e. pretty soon:</p>
                <pre class="language-javascript line-numbers"><code>
const wait = ms => new Promise(resolve => setTimeout(resolve, ms));

wait().then(() => console.log(4));
Promise.resolve().then(() => console.log(2)).then(() => console.log(3));
console.log(1); // 1, 2, 3, 4
                </code></pre>
            </section>
            <section class="main-section" id="Nesting">
                <header>NESTING</header>
                <p>Simple promise chains are best kept flat without nesting, as nesting can be a result of careless composition. See <a href="technical_page.html#Common_mistakes">common mistakes.</a></p>
                <p>Nesting is a control structure to limit the scope of  statements. Specifically, a nested <code class="language-javascript">catch</code> only catches failures in its scope and below, not errors higher up in the chain outside the nested scope. When used correctly, this gives greater precision in error recovery:</p>
                <pre class="language-javascript line-numbers"><code>
doSomethingCritical()
    .then(result => doSomethingOptional(result)
    .then(optionalResult => doSomethingExtraNice(optionalResult))
    .catch(e => {})) // Ignore if optional stuff fails; proceed.
    .then(() => moreCriticalStuff())
    .catch(e => console.error("Critical failure: " + e.message));

                </code></pre>
                <p>Note that the optional steps here are nested, not from the indentation, but from the precarious placement of the outer <code class="language-javascript">(</code> and <code class="language-javascript">)</code> around them.</p>
                <p>The inner neutralizing <code class="language-javascript">catch</code> statement only catches failures from <code class="language-javascript">doSomethingOptional()</code> and <code class="language-javascript">doSomethingExtraNice()</code>, after which the code resumes with <code class="language-javascript">moreCriticalStuff()</code>. Importantly, if <code class="language-javascript">doSomethingCritical()</code> fails, its error is caught by the final (outer) <code class="language-javascript">catch</code> only.</p>
            </section>
            <section class="main-section" id="Common_mistakes">
                <header>COMMON MISTAKES</header>
                <p>Here are some common mistakes to watch out for when composing promise chains. Several of these mistakes manifest in the following example:</p>
                <pre class="language-javascript line-numbers"><code>
// Bad example! Spot 3 mistakes!

doSomething().then(function(result) {
doSomethingElse(result) // Forgot to return promise from inner chain + unnecessary nesting
.then(newResult => doThirdThing(newResult));
}).then(() => doFourthThing());
// Forgot to terminate chain with a catch!
                </code></pre>
                <p> The first mistake is to not chain things together properly. This happens when we create a new promise but forget to return it. As a consequence, the chain is broken, or rather, we have two independent chains racing. This means <code class="language-javascript">doFourthThing()</code> won't wait for <code class="language-javascript">doSomethingElse()</code> or <code class="language-javascript">doThirdThing()</code> to finish, and will run in parallel with them, likely unintended. Separate chains also have separate error handling, leading to uncaught errors.</p>
                <p>The second mistake is to nest unnecessarily, enabling the first mistake. Nesting also limits the scope of inner error handlers, which - if unintended - can lead to uncaught errors. A variant of this is the promise constructor anti-pattern, which combines nesting with redundant use of the promise constructor to wrap code that already uses promises.</p>
                <p>The third mistake is forgetting to terminate chains with catch. Unterminated promise chains lead to uncaught promise rejections in most browsers.</p>
                <p>A good rule-of-thumb is to always either return or terminate promise chains, and as soon as you get a new promise, return it immediately, to flatten things:</p>
                <pre class="language-javascript line-numbers"><code>
doSomething()
    .then(function(result) {
    return doSomethingElse(result);
    })
    .then(newResult => doThirdThing(newResult))
    .then(() => doFourthThing())
    .catch(error => console.error(error));
                </code></pre>

                <p>
                    Note that <code class="language-javascript">() => x</code> is short for <code class="language-javascript">() => { return x; }</code>.<br>
                    Now we have a single deterministic chain with proper error handling.<br>
                    Using <code class="language-javascript">async/await</code> addresses most, if not all of these problems - the tradeoff being that the most common mistake with that syntax is forgetting the await keyword.
                </p>    
            </section>
            <section class="main-section" id="When_promises_and_tasks_collide">
                <header>WHEN PROMISES AND TASKS COLLIDE</header>
                <p>If you run into situations in which you have promises and tasks (such as events or callbacks) which are firing in unpredictable orders, it's possible you may benefit from using a microtask to check status or balance out your promises when promises are created conditionally.
                    If you think microtasks may help solve this problem, see the microtask guide to learn more about how to use <code class="language-javascript">queueMicrotask()</code> to enqueue a function as a microtask.</p>
            </section>
        </main>
    </body>
</html>

